<robot name="my_robot">

  <link name="link_0">
    <visual><geometry><box size="0.250 0.02 0.02"/></geometry><origin xyz="0.125 0 0" rpy="0 0 0"/></visual>
    <collision><geometry><box size="0.250 0.02 0.02"/></geometry><origin xyz="0.125 0 0" rpy="0 0 0"/></collision>
  </link>

  <link name="link_1">
    <visual><geometry><box size="0.100 0.02 0.02"/></geometry><origin xyz="0.050 0 0" rpy="0 0 0"/></visual>
    <collision><geometry><box size="0.100 0.02 0.02"/></geometry><origin xyz="0.050 0 0" rpy="0 0 0"/></collision>
  </link>

  <joint name="joint_0" type="revolute">
    <parent link="link_0"/><child link="link_1"/><origin xyz="0.250 0 0" rpy="0 0 0"/><axis xyz="0 0 1"/>
    <limit lower="-3.1416" upper="3.1416" effort="10" velocity="1.0"/>
  </joint>

  <link name="end_effector"/>

  <joint name="joint_1" type="revolute">
    <parent link="link_1"/><child link="end_effector"/><origin xyz="0.100 0 0" rpy="0 0 0"/><axis xyz="0 0 1"/>
    <limit lower="-3.1416" upper="3.1416" effort="10" velocity="1.0"/>
  </joint>
</robot>